<?xml version="1.0" encoding="utf-8"?>
<!-- =================================================================================== -->
<!--   Copyright 2020 ANYbotics, https://www.anybotics.com                               -->
<!-- =================================================================================== -->
<!-- This file contains the description of the ANYmal C robot. -->
<robot name="anymal"
    xmlns:controller="http://playerstage.sourceforge.net/gazebo/xmlschema/#controller"
    xmlns:interface="http://playerstage.sourceforge.net/gazebo/xmlschema/#interface"
    xmlns:sensor="http://playerstage.sourceforge.net/gazebo/xmlschema/#sensor"
    xmlns:xacro="http://playerstage.sourceforge.net/gazebo/xmlschema/#interface">
    <!-- Base link -->
    <link name="base_link">
        <visual>
            <origin rpy="0 0 0" xyz="0 0 0"/>
            <geometry>
                <mesh filename="package://robot_properties_solo/resources/meshes/anymal/dae/base.dae" scale="1.0 1.0 1.0"/>
            </geometry>
        </visual>
        <collision>
            <origin rpy="0 0 0" xyz="0 0 0"/>
            <geometry>
                <box size="0.58 0.14 0.18"/>
            </geometry>
        </collision>
        <collision>
            <origin rpy="0 1.57079632679 0" xyz="0.2175 0.07 0"/>
            <geometry>
                <cylinder length="0.145" radius="0.09"/>
            </geometry>
        </collision>
        <collision>
            <origin rpy="0 1.57079632679 0" xyz="-0.2175 0.07 0"/>
            <geometry>
                <cylinder length="0.145" radius="0.09"/>
            </geometry>
        </collision>
        <collision>
            <origin rpy="0 1.57079632679 0" xyz="0.2175 -0.07 0"/>
            <geometry>
                <cylinder length="0.145" radius="0.09"/>
            </geometry>
        </collision>
        <collision>
            <origin rpy="0 1.57079632679 0" xyz="-0.2175 -0.07 0"/>
            <geometry>
                <cylinder length="0.145" radius="0.09"/>
            </geometry>
        </collision>
        <!-- Shell self filtering -->
        <self_filter>
            <origin rpy="0 0 0" xyz="0 0 0"/>
            <geometry>
                <box size="1.05 0.5 0.5"/>
            </geometry>
        </self_filter>
    </link>
    <!-- Fixed joint to add dummy inertia link -->
    <joint name="base_to_base_inertia" type="fixed">
        <parent link="base_link"/>
        <child link="base_inertia"/>
        <origin rpy="0 0 0" xyz="0 0 0"/>
    </joint>
    <!-- Dummy inertia link, because KDL cannot have inertia on the base link -->
    <link name="base_inertia">
        <inertial>
            <origin rpy="0 0 0" xyz="-0.018 -0.002 0.024"/>
            <mass value="6.222"/>
            <inertia ixx="0.017938806" ixy="0.00387963" ixz="0.001500772" iyy="0.370887745" iyz="6.8963e-05" izz="0.372497653"/>
        </inertial>
    </link>
    <!-- Fixed joint base topshell -->
    <joint name="base_top_shell" type="fixed">
        <parent link="base_link"/>
        <child link="top_shell"/>
        <origin rpy="0 0 0" xyz="0 0 0"/>
    </joint>
    <!-- Top shell link -->
    <link name="top_shell">
        <visual>
            <origin rpy="0 0 0" xyz="0 0 0"/>
            <geometry>
                <mesh filename="package://robot_properties_solo/resources/meshes/anymal/dae/top_shell.dae" scale="1.0 1.0 1.0"/>
            </geometry>
        </visual>
        <inertial>
            <origin rpy="0 0 0" xyz="-0.00777 -0.00013 0.06523"/>
            <mass value="0.534"/>
            <inertia ixx="0.00664789486" ixy="1.247923e-05" ixz="0.00053990097" iyy="0.02587392411" iyz="3.7614e-07" izz="0.03152303792"/>
        </inertial>
    </link>
    <!-- Fixed joint base topshell -->
    <joint name="base_bottom_shell" type="fixed">
        <parent link="base_link"/>
        <child link="bottom_shell"/>
        <origin rpy="0 0 0" xyz="0 0 0"/>
    </joint>
    <!-- Bottom shell link -->
    <link name="bottom_shell">
        <visual>
            <origin rpy="0 0 0" xyz="0 0 0"/>
            <geometry>
                <mesh filename="package://robot_properties_solo/resources/meshes/anymal/dae/bottom_shell.dae" scale="1.0 1.0 1.0"/>
            </geometry>
        </visual>
        <inertial>
            <origin rpy="0 0 0" xyz="-0.00333 1e-05 -0.07705"/>
            <mass value="1.15"/>
            <inertia ixx="0.00927353677" ixy="5.41222e-06" ixz="9.039821e-05" iyy="0.06134388239" iyz="2.3042e-07" izz="0.06853531465"/>
        </inertial>
    </link>
    <!-- Fixed joint base remote -->
    <joint name="base_remote" type="fixed">
        <parent link="base_link"/>
        <child link="remote"/>
        <origin rpy="0 0 0" xyz="0 0 0"/>
    </joint>
    <!-- Remote link -->
    <link name="remote">
        <visual>
            <origin rpy="0 0 0" xyz="0 0 0"/>
            <geometry>
                <mesh filename="package://robot_properties_solo/resources/meshes/anymal/dae/remote.dae" scale="1.0 1.0 1.0"/>
            </geometry>
        </visual>
        <inertial>
            <origin rpy="0 0 0" xyz="-0.171 0.002 0.096"/>
            <mass value="0.3262"/>
            <inertia ixx="0.000528486" ixy="4.547e-05" ixz="1.10327e-05" iyy="0.001165035" iyz="7.4e-07" izz="0.00124026"/>
        </inertial>
    </link>
    <!-- Fixed joint base handle -->
    <joint name="base_handle" type="fixed">
        <parent link="base_link"/>
        <child link="handle"/>
        <origin rpy="0 0 0" xyz="0 0 0"/>
    </joint>
    <!-- Handle link -->
    <link name="handle">
        <visual>
            <origin rpy="0 0 0" xyz="0 0 0"/>
            <geometry>
                <mesh filename="package://robot_properties_solo/resources/meshes/anymal/dae/handle.dae" scale="1.0 1.0 1.0"/>
            </geometry>
        </visual>
        <inertial>
            <origin rpy="0 0 0" xyz="0.37801 0.0 0.1372"/>
            <mass value="0.314"/>
            <inertia ixx="0.001525739" ixy="0.0" ixz="6.272e-05" iyy="0.00071584" iyz="1e-09" izz="0.001164779"/>
        </inertial>
    </link>
    <!-- Fixed joint base face -->
    <joint name="base_face_front" type="fixed">
        <parent link="base_link"/>
        <child link="face_front"/>
        <origin rpy="0 0 -0.0" xyz="0.4145 0 0"/>
    </joint>
    <!-- Shell link -->
    <link name="face_front">
        <visual>
            <origin rpy="0 0 0" xyz="0 0 0"/>
            <geometry>
                <mesh filename="package://robot_properties_solo/resources/meshes/anymal/dae/face.dae" scale="1.0 1.0 1.0"/>
            </geometry>
        </visual>
        <collision>
            <origin rpy="0 0 0" xyz="0.055 0 0"/>
            <geometry>
                <box size="0.11 0.14 0.18"/>
            </geometry>
        </collision>
        <collision>
            <origin rpy="0 1.57079632679 0" xyz="0.055 0.07 0"/>
            <geometry>
                <cylinder length="0.11" radius="0.09"/>
            </geometry>
        </collision>
        <collision>
            <origin rpy="0 1.57079632679 0" xyz="0.055 -0.07 0"/>
            <geometry>
                <cylinder length="0.11" radius="0.09"/>
            </geometry>
        </collision>
        <inertial>
            <origin rpy="0 0 0" xyz="0.042 -0.001 0.004"/>
            <mass value="0.73"/>
            <inertia ixx="0.005238611" ixy="1.7609e-05" ixz="7.2167e-05" iyy="0.002643098" iyz="1.9548e-05" izz="0.004325938"/>
        </inertial>
    </link>
    <!-- Camera joint -->
    <!-- Is located between the two back screw holes at ground level. -->
    <joint name="face_front_to_depth_camera_front_camera" type="fixed">
        <parent link="face_front"/>
        <child link="depth_camera_front_camera"/>
        <origin rpy="0.0 0.523598775598 0" xyz="0.04715 0.0 -0.0292"/>
    </joint>
    <!-- Camera link -->
    <link name="depth_camera_front_camera">
        <visual>
            <origin rpy="0 0 0" xyz="0.0 0.0 0.0"/>
            <geometry>
                <mesh filename="package://robot_properties_solo/resources/meshes/anymal/dae/depth_camera.dae" scale="1.0 1.0 1.0"/>
            </geometry>
        </visual>
        <inertial>
            <origin rpy="0 0 0" xyz="-0.021 -0.002 0.025"/>
            <mass value="0.16043"/>
            <inertia ixx="0.000637051" ixy="0.000484569" ixz="0.000424211" iyy="0.000929402" iyz="5.138e-06" izz="0.000484569"/>
        </inertial>
    </link>
    <!-- Camera parent joint -->
    <!-- Frame lies on the left ir camera according to any_realsense2_camera urdf. -->
    <joint name="depth_camera_front_camera_to_camera_parent" type="fixed">
        <parent link="depth_camera_front_camera"/>
        <child link="depth_camera_front_camera_parent"/>
        <origin rpy="0.0 0.0 0.0" xyz="0.0255 0.0175 0.0"/>
    </joint>
    <!-- Camera parent link -->
    <link name="depth_camera_front_camera_parent"/>
    <!-- Depth optical frame joint -->
    <joint name="depth_camera_front_camera_parent_to_depth_optical_frame" type="fixed">
        <parent link="depth_camera_front_camera_parent"/>
        <child link="depth_camera_front_depth_optical_frame"/>
        <origin rpy="-1.57079632679 0.0 -1.57079632679" xyz="0.0 0.0 0.0"/>
    </joint>
    <!-- Depth optical frame link -->
    <link name="depth_camera_front_depth_optical_frame"/>
    <!-- Camera color frame joint -->
    <joint name="depth_camera_front_camera_parent_to_color_frame" type="fixed">
        <parent link="depth_camera_front_camera_parent"/>
        <child link="depth_camera_front_color_frame"/>
        <origin rpy="0 0 0" xyz="0 0.015 0"/>
    </joint>
    <!-- Camera color frame link -->
    <link name="depth_camera_front_color_frame"/>
    <!-- Camera color optical joint -->
    <joint name="depth_camera_front_color_frame_to_color_optical_frame" type="fixed">
        <parent link="depth_camera_front_color_frame"/>
        <child link="depth_camera_front_color_optical_frame"/>
        <origin rpy="-1.57079632679 0.0 -1.57079632679" xyz="0.0 0.0 0.0"/>
    </joint>
    <!-- Camera color optical link -->
    <link name="depth_camera_front_color_optical_frame"/>
    <!-- Camera joint -->
    <!-- Is located in the center of the mounting points. -->
    <joint name="face_front_to_wide_angle_camera_front_camera" type="fixed">
        <parent link="face_front"/>
        <child link="wide_angle_camera_front_camera"/>
        <origin rpy="0 0 0" xyz="0.09850 0.0 0.01497"/>
    </joint>
    <!-- Camera link -->
    <link name="wide_angle_camera_front_camera">
        <visual>
            <origin rpy="0 0 0" xyz="0.0 0.0 0.0"/>
            <geometry>
                <mesh filename="package://robot_properties_solo/resources/meshes/anymal/dae/wide_angle_camera.dae" scale="1.0 1.0 1.0"/>
            </geometry>
        </visual>
        <inertial>
            <origin rpy="0 0 0" xyz="-0.053 -0.001 0.025"/>
            <mass value="0.287"/>
            <inertia ixx="0.000559232" ixy="1.6875e-05" ixz="0.000423761" iyy="0.000946504" iyz="1.3234e-07" izz="0.000493052"/>
        </inertial>
    </link>
    <!-- Camera parent joint -->
    <joint name="wide_angle_camera_front_camera_to_camera_parent" type="fixed">
        <parent link="wide_angle_camera_front_camera"/>
        <child link="wide_angle_camera_front_camera_parent"/>
        <origin rpy="-1.57079632679 0.0 -1.57079632679" xyz="0.0 0.0 0.0"/>
    </joint>
    <!-- Camera parent link -->
    <link name="wide_angle_camera_front_camera_parent"/>
    <!-- Fixed joint base face -->
    <joint name="base_face_rear" type="fixed">
        <parent link="base_link"/>
        <child link="face_rear"/>
        <origin rpy="0 0 3.14159265359" xyz="-0.4145 0 0"/>
    </joint>
    <!-- Shell link -->
    <link name="face_rear">
        <visual>
            <origin rpy="0 0 0" xyz="0 0 0"/>
            <geometry>
                <mesh filename="package://robot_properties_solo/resources/meshes/anymal/dae/face.dae" scale="1.0 1.0 1.0"/>
            </geometry>
        </visual>
        <collision>
            <origin rpy="0 0 0" xyz="0.055 0 0"/>
            <geometry>
                <box size="0.11 0.14 0.18"/>
            </geometry>
        </collision>
        <collision>
            <origin rpy="0 1.57079632679 0" xyz="0.055 0.07 0"/>
            <geometry>
                <cylinder length="0.11" radius="0.09"/>
            </geometry>
        </collision>
        <collision>
            <origin rpy="0 1.57079632679 0" xyz="0.055 -0.07 0"/>
            <geometry>
                <cylinder length="0.11" radius="0.09"/>
            </geometry>
        </collision>
        <inertial>
            <origin rpy="0 0 0" xyz="0.042 -0.001 0.004"/>
            <mass value="0.73"/>
            <inertia ixx="0.005238611" ixy="1.7609e-05" ixz="7.2167e-05" iyy="0.002643098" iyz="1.9548e-05" izz="0.004325938"/>
        </inertial>
    </link>
    <!-- Camera joint -->
    <!-- Is located between the two back screw holes at ground level. -->
    <joint name="face_rear_to_depth_camera_rear_camera" type="fixed">
        <parent link="face_rear"/>
        <child link="depth_camera_rear_camera"/>
        <origin rpy="0.0 0.523598775598 0" xyz="0.04715 0.0 -0.0292"/>
    </joint>
    <!-- Camera link -->
    <link name="depth_camera_rear_camera">
        <visual>
            <origin rpy="0 0 0" xyz="0.0 0.0 0.0"/>
            <geometry>
                <mesh filename="package://robot_properties_solo/resources/meshes/anymal/dae/depth_camera.dae" scale="1.0 1.0 1.0"/>
            </geometry>
        </visual>
        <inertial>
            <origin rpy="0 0 0" xyz="-0.021 -0.002 0.025"/>
            <mass value="0.16043"/>
            <inertia ixx="0.000637051" ixy="0.000484569" ixz="0.000424211" iyy="0.000929402" iyz="5.138e-06" izz="0.000484569"/>
        </inertial>
    </link>
    <!-- Camera parent joint -->
    <!-- Frame lies on the left ir camera according to any_realsense2_camera urdf. -->
    <joint name="depth_camera_rear_camera_to_camera_parent" type="fixed">
        <parent link="depth_camera_rear_camera"/>
        <child link="depth_camera_rear_camera_parent"/>
        <origin rpy="0.0 0.0 0.0" xyz="0.0255 0.0175 0.0"/>
    </joint>
    <!-- Camera parent link -->
    <link name="depth_camera_rear_camera_parent"/>
    <!-- Depth optical frame joint -->
    <joint name="depth_camera_rear_camera_parent_to_depth_optical_frame" type="fixed">
        <parent link="depth_camera_rear_camera_parent"/>
        <child link="depth_camera_rear_depth_optical_frame"/>
        <origin rpy="-1.57079632679 0.0 -1.57079632679" xyz="0.0 0.0 0.0"/>
    </joint>
    <!-- Depth optical frame link -->
    <link name="depth_camera_rear_depth_optical_frame"/>
    <!-- Camera color frame joint -->
    <joint name="depth_camera_rear_camera_parent_to_color_frame" type="fixed">
        <parent link="depth_camera_rear_camera_parent"/>
        <child link="depth_camera_rear_color_frame"/>
        <origin rpy="0 0 0" xyz="0 0.015 0"/>
    </joint>
    <!-- Camera color frame link -->
    <link name="depth_camera_rear_color_frame"/>
    <!-- Camera color optical joint -->
    <joint name="depth_camera_rear_color_frame_to_color_optical_frame" type="fixed">
        <parent link="depth_camera_rear_color_frame"/>
        <child link="depth_camera_rear_color_optical_frame"/>
        <origin rpy="-1.57079632679 0.0 -1.57079632679" xyz="0.0 0.0 0.0"/>
    </joint>
    <!-- Camera color optical link -->
    <link name="depth_camera_rear_color_optical_frame"/>
    <!-- Camera joint -->
    <!-- Is located in the center of the mounting points. -->
    <joint name="face_rear_to_wide_angle_camera_rear_camera" type="fixed">
        <parent link="face_rear"/>
        <child link="wide_angle_camera_rear_camera"/>
        <origin rpy="0 0 0" xyz="0.09850 0.0 0.01497"/>
    </joint>
    <!-- Camera link -->
    <link name="wide_angle_camera_rear_camera">
        <visual>
            <origin rpy="0 0 0" xyz="0.0 0.0 0.0"/>
            <geometry>
                <mesh filename="package://robot_properties_solo/resources/meshes/anymal/dae/wide_angle_camera.dae" scale="1.0 1.0 1.0"/>
            </geometry>
        </visual>
        <inertial>
            <origin rpy="0 0 0" xyz="-0.053 -0.001 0.025"/>
            <mass value="0.287"/>
            <inertia ixx="0.000559232" ixy="1.6875e-05" ixz="0.000423761" iyy="0.000946504" iyz="1.3234e-07" izz="0.000493052"/>
        </inertial>
    </link>
    <!-- Camera parent joint -->
    <joint name="wide_angle_camera_rear_camera_to_camera_parent" type="fixed">
        <parent link="wide_angle_camera_rear_camera"/>
        <child link="wide_angle_camera_rear_camera_parent"/>
        <origin rpy="-1.57079632679 0.0 -1.57079632679" xyz="0.0 0.0 0.0"/>
    </joint>
    <!-- Camera parent link -->
    <link name="wide_angle_camera_rear_camera_parent"/>
    <!-- Fixed joint base battery -->
    <joint name="base_battery" type="fixed">
        <parent link="base_link"/>
        <child link="battery"/>
        <origin rpy="0 0 0" xyz="0 0 0"/>
    </joint>
    <!-- Shell link -->
    <link name="battery">
        <visual>
            <origin rpy="0 0 0" xyz="0 0 0"/>
            <geometry>
                <mesh filename="package://robot_properties_solo/resources/meshes/anymal/dae/battery.dae" scale="1.0 1.0 1.0"/>
            </geometry>
        </visual>
        <inertial>
            <origin rpy="0 0 0" xyz="-0.00067 -0.00023 -0.03362"/>
            <mass value="5.53425"/>
            <inertia ixx="0.00749474794" ixy="0.00016686282" ixz="7.82763e-05" iyy="0.0722338913" iyz="1.42902e-06" izz="0.07482717535"/>
        </inertial>
    </link>
    <!-- Fixed joint to add docking  -->
    <joint name="base_to_docking_hatch_cover" type="fixed">
        <parent link="base_link"/>
        <child link="docking_hatch_cover"/>
        <origin rpy="0 0 0" xyz="0.343 0.0 -0.07"/>
    </joint>
    <!-- Hatch cover link -->
    <link name="docking_hatch_cover">
        <!--  TODO(fgiraldez): add visual    -->
        <inertial>
            <origin rpy="0 0 0" xyz="-0.003 0.0 0.005"/>
            <mass value="0.065"/>
            <inertia ixx="0.00063283" ixy="0.0" ixz="3.45e-07" iyy="0.00110971" iyz="0.0" izz="0.00171883"/>
        </inertial>
    </link>
    <link name="imu_link">
        <visual>
            <origin rpy="0 0 0" xyz="0 0 0.005"/>
            <geometry>
                <box size="0.024 0.024 0.01"/>
            </geometry>
            <material name="orange"/>
        </visual>
        <collision>
            <origin rpy="0 0 0" xyz="0 0 0.005"/>
            <geometry>
                <box size="0.024 0.024 0.01"/>
            </geometry>
        </collision>
        <inertial>
            <mass value="0.01"/>
            <origin xyz="0 0 0"/>
            <inertia ixx="5.63333333333e-07" ixy="0.0" ixz="0.0" iyy="9.6e-07" iyz="0.0" izz="5.63333333333e-07"/>
        </inertial>
    </link>
    <joint name="imu_joint" type="fixed">
        <parent link="base_link"/>
        <child link="imu_link"/>
        <origin rpy="0.0 0.0 0.0" xyz="0.2488 0.00835 0.04628"/>
    </joint>
    <!-- Camera joint -->
    <!-- Is located between the two back screw holes at ground level. -->
    <joint name="base_to_depth_camera_left_camera" type="fixed">
        <parent link="base_link"/>
        <child link="depth_camera_left_camera"/>
        <origin rpy="0.0 0.523598775598 1.57079632679" xyz="0.0 0.07646 0.02905"/>
    </joint>
    <!-- Camera link -->
    <link name="depth_camera_left_camera">
        <visual>
            <origin rpy="0 0 0" xyz="0.0 0.0 0.0"/>
            <geometry>
                <mesh filename="package://robot_properties_solo/resources/meshes/anymal/dae/depth_camera.dae" scale="1.0 1.0 1.0"/>
            </geometry>
        </visual>
        <inertial>
            <origin rpy="0 0 0" xyz="-0.021 -0.002 0.025"/>
            <mass value="0.16043"/>
            <inertia ixx="0.000637051" ixy="0.000484569" ixz="0.000424211" iyy="0.000929402" iyz="5.138e-06" izz="0.000484569"/>
        </inertial>
    </link>
    <!-- Camera parent joint -->
    <!-- Frame lies on the left ir camera according to any_realsense2_camera urdf. -->
    <joint name="depth_camera_left_camera_to_camera_parent" type="fixed">
        <parent link="depth_camera_left_camera"/>
        <child link="depth_camera_left_camera_parent"/>
        <origin rpy="0.0 0.0 0.0" xyz="0.0255 0.0175 0.0"/>
    </joint>
    <!-- Camera parent link -->
    <link name="depth_camera_left_camera_parent"/>
    <!-- Depth optical frame joint -->
    <joint name="depth_camera_left_camera_parent_to_depth_optical_frame" type="fixed">
        <parent link="depth_camera_left_camera_parent"/>
        <child link="depth_camera_left_depth_optical_frame"/>
        <origin rpy="-1.57079632679 0.0 -1.57079632679" xyz="0.0 0.0 0.0"/>
    </joint>
    <!-- Depth optical frame link -->
    <link name="depth_camera_left_depth_optical_frame"/>
    <!-- Camera color frame joint -->
    <joint name="depth_camera_left_camera_parent_to_color_frame" type="fixed">
        <parent link="depth_camera_left_camera_parent"/>
        <child link="depth_camera_left_color_frame"/>
        <origin rpy="0 0 0" xyz="0 0.015 0"/>
    </joint>
    <!-- Camera color frame link -->
    <link name="depth_camera_left_color_frame"/>
    <!-- Camera color optical joint -->
    <joint name="depth_camera_left_color_frame_to_color_optical_frame" type="fixed">
        <parent link="depth_camera_left_color_frame"/>
        <child link="depth_camera_left_color_optical_frame"/>
        <origin rpy="-1.57079632679 0.0 -1.57079632679" xyz="0.0 0.0 0.0"/>
    </joint>
    <!-- Camera color optical link -->
    <link name="depth_camera_left_color_optical_frame"/>
    <!-- Camera joint -->
    <!-- Is located between the two back screw holes at ground level. -->
    <joint name="base_to_depth_camera_right_camera" type="fixed">
        <parent link="base_link"/>
        <child link="depth_camera_right_camera"/>
        <origin rpy="0.0 0.523598775598 -1.57079632679" xyz="0.0 -0.07646 0.02905"/>
    </joint>
    <!-- Camera link -->
    <link name="depth_camera_right_camera">
        <visual>
            <origin rpy="0 0 0" xyz="0.0 0.0 0.0"/>
            <geometry>
                <mesh filename="package://robot_properties_solo/resources/meshes/anymal/dae/depth_camera.dae" scale="1.0 1.0 1.0"/>
            </geometry>
        </visual>
        <inertial>
            <origin rpy="0 0 0" xyz="-0.021 -0.002 0.025"/>
            <mass value="0.16043"/>
            <inertia ixx="0.000637051" ixy="0.000484569" ixz="0.000424211" iyy="0.000929402" iyz="5.138e-06" izz="0.000484569"/>
        </inertial>
    </link>
    <!-- Camera parent joint -->
    <!-- Frame lies on the left ir camera according to any_realsense2_camera urdf. -->
    <joint name="depth_camera_right_camera_to_camera_parent" type="fixed">
        <parent link="depth_camera_right_camera"/>
        <child link="depth_camera_right_camera_parent"/>
        <origin rpy="0.0 0.0 0.0" xyz="0.0255 0.0175 0.0"/>
    </joint>
    <!-- Camera parent link -->
    <link name="depth_camera_right_camera_parent"/>
    <!-- Depth optical frame joint -->
    <joint name="depth_camera_right_camera_parent_to_depth_optical_frame" type="fixed">
        <parent link="depth_camera_right_camera_parent"/>
        <child link="depth_camera_right_depth_optical_frame"/>
        <origin rpy="-1.57079632679 0.0 -1.57079632679" xyz="0.0 0.0 0.0"/>
    </joint>
    <!-- Depth optical frame link -->
    <link name="depth_camera_right_depth_optical_frame"/>
    <!-- Camera color frame joint -->
    <joint name="depth_camera_right_camera_parent_to_color_frame" type="fixed">
        <parent link="depth_camera_right_camera_parent"/>
        <child link="depth_camera_right_color_frame"/>
        <origin rpy="0 0 0" xyz="0 0.015 0"/>
    </joint>
    <!-- Camera color frame link -->
    <link name="depth_camera_right_color_frame"/>
    <!-- Camera color optical joint -->
    <joint name="depth_camera_right_color_frame_to_color_optical_frame" type="fixed">
        <parent link="depth_camera_right_color_frame"/>
        <child link="depth_camera_right_color_optical_frame"/>
        <origin rpy="-1.57079632679 0.0 -1.57079632679" xyz="0.0 0.0 0.0"/>
    </joint>
    <!-- Camera color optical link -->
    <link name="depth_camera_right_color_optical_frame"/>
    <!-- parent to cage joint, located between mounting plate on trunk and the cage -->
    <joint name="base_to_lidar_cage" type="fixed">
        <parent link="base_link"/>
        <child link="lidar_cage"/>
        <origin rpy="0 0 0" xyz="-0.364 0.0 0.0735"/>
    </joint>
    <!-- Velodyne cage link -->
    <link name="lidar_cage">
        <visual>
            <origin rpy="0.0 0.0 0.0" xyz="0.0 0.0 0.0"/>
            <geometry>
                <mesh filename="package://robot_properties_solo/resources/meshes/anymal/dae/lidar_cage.dae" scale="1.0 1.0 1.0"/>
            </geometry>
        </visual>
        <collision>
            <origin rpy="0 0 0" xyz="0 0 0.06"/>
            <geometry>
                <cylinder length="0.12" radius="0.07"/>
            </geometry>
        </collision>
        <inertial>
            <origin rpy="0.0 0.0 0.0" xyz="0.002 0.0 0.099"/>
            <mass value="0.545"/>
            <inertia ixx="0.003156254" ixy="0.0" ixz="1.0992e-05" iyy="0.002357216" iyz="0.0" izz="0.001326455"/>
        </inertial>
    </link>
    <!-- parent to sensor joint -->
    <joint name="lidar_cage_to_lidar" type="fixed">
        <parent link="lidar_cage"/>
        <child link="lidar"/>
        <origin rpy="0.0 0.0 -1.57079632679" xyz="0.0 0.0 0.0687"/>
    </joint>
    <!-- Velodyne sensor link -->
    <link name="lidar">
        <inertial>
            <origin rpy="0.0 0.0 0.0" xyz="-0.012 0.001 -0.008"/>
            <mass value="0.695"/>
            <inertia ixx="0.000846765" ixy="6.9565e-05" ixz="0.00027111" iyy="0.001367583" iyz="5.8984e-05" izz="0.001363673"/>
        </inertial>
        <visual>
            <origin xyz="0 0 0"/>
            <geometry>
                <mesh filename="package://robot_properties_solo/resources/meshes/anymal/dae/lidar.dae"/>
            </geometry>
        </visual>
    </link>
    <!-- joint base HAA -->
    <joint name="base_FL_HAA" type="fixed">
        <parent link="base_link"/>
        <child link="FL_HAA"/>
        <origin rpy="2.61799387799 0 0.0" xyz="0.2999 0.104 0.0"/>
    </joint>
    <!-- Drive link -->
    <link name="FL_HAA">
        <visual>
            <origin rpy="0 0 0" xyz="0 0 0"/>
            <geometry>
                <mesh filename="package://robot_properties_solo/resources/meshes/anymal/dae/drive.dae" scale="1.0 1.0 1.0"/>
            </geometry>
        </visual>
        <inertial>
            <origin rpy="0 0 0" xyz="-0.063 7e-05 0.00046"/>
            <mass value="2.04"/>
            <inertia ixx="0.001053013" ixy="4.527e-05" ixz="8.855e-05" iyy="0.001805509" iyz="9.909e-05" izz="0.001765827"/>
        </inertial>
    </link>
    <!-- joint Drive output -->
    <joint name="FL_HAA" type="revolute">
        <parent link="FL_HAA"/>
        <child link="FL_HIP"/>
        <origin rpy="0 0 0" xyz="0 0 0"/>
        <axis xyz="1 0 0"/>
        <limit effort="80.0" lower="-0.72" upper="0.72" velocity="7.5"/>
        <dynamics damping="0.0" friction="0.0"/>
    </joint>
    <!-- Drive output link -->
    <link name="FL_HIP">
        <inertial>
            <origin rpy="0 0 0" xyz="0 0 0"/>
            <mass value="0.001"/>
            <inertia ixx="0.000001" ixy="0.0" ixz="0.0" iyy="0.000001" iyz="0.0" izz="0.000001"/>
        </inertial>
    </link>
    <!-- joint HAA hip -->
    <joint name="FL_HIP_FL_hip_fixed" type="fixed">
        <parent link="FL_HIP"/>
        <child link="FL_hip_fixed"/>
        <origin rpy="-2.61799387799 0 0.0" xyz="0 0 0"/>
    </joint>
    <!-- Hip link -->
    <link name="FL_hip_fixed">
        <visual>
            <origin rpy="0 0 0.0" xyz="0 0 0"/>
            <geometry>
                <mesh filename="package://robot_properties_solo/resources/meshes/anymal/dae/hip_l.dae" scale="1.0 1.0 1.0"/>
            </geometry>
        </visual>
        <inertial>
            <origin rpy="0 0 0" xyz="0.048 0.008 -0.003"/>
            <mass value="0.74"/>
            <inertia ixx="0.001393106" ixy="8.4012e-05" ixz="2.3378e-05" iyy="0.003798579" iyz="7.1319e-05" izz="0.003897509"/>
        </inertial>
    </link>
    <!-- joint hip HFE -->
    <joint name="FL_hip_fixed_FL_HFE" type="fixed">
        <parent link="FL_hip_fixed"/>
        <child link="FL_HFE"/>
        <origin rpy="0 0 1.57079632679" xyz="0.0599 0.08381 0.0"/>
    </joint>
    <!-- Drive link -->
    <link name="FL_HFE">
        <visual>
            <origin rpy="0 0 0" xyz="0 0 0"/>
            <geometry>
                <mesh filename="package://robot_properties_solo/resources/meshes/anymal/dae/drive.dae" scale="1.0 1.0 1.0"/>
            </geometry>
        </visual>
        <collision>
            <origin rpy="0 1.57079632679 0" xyz="-0.07 0 0"/>
            <geometry>
                <cylinder length="0.14" radius="0.05"/>
            </geometry>
        </collision>
        <inertial>
            <origin rpy="0 0 0" xyz="-0.063 7e-05 0.00046"/>
            <mass value="2.04"/>
            <inertia ixx="0.001053013" ixy="4.527e-05" ixz="8.855e-05" iyy="0.001805509" iyz="9.909e-05" izz="0.001765827"/>
        </inertial>
    </link>
    <!-- joint Drive output -->
    <joint name="FL_HFE" type="revolute">
        <parent link="FL_HFE"/>
        <child link="FL_THIGH"/>
        <origin rpy="0 0 0" xyz="0 0 0"/>
        <axis xyz="1 0 0"/>
        <limit effort="80.0" lower="-9.42477796077" upper="9.42477796077" velocity="7.5"/>
        <dynamics damping="0.0" friction="0.0"/>
    </joint>
    <!-- Drive output link -->
    <link name="FL_THIGH">
        <inertial>
            <origin rpy="0 0 0" xyz="0 0 0"/>
            <mass value="0.001"/>
            <inertia ixx="0.000001" ixy="0.0" ixz="0.0" iyy="0.000001" iyz="0.0" izz="0.000001"/>
        </inertial>
    </link>
    <!-- joint HFE thigh -->
    <joint name="FL_THIGH_FL_thigh_fixed" type="fixed">
        <parent link="FL_THIGH"/>
        <child link="FL_thigh_fixed"/>
        <origin rpy="0 0 -1.57079632679" xyz="0 0 0"/>
    </joint>
    <!-- Thigh link -->
    <link name="FL_thigh_fixed">
        <visual>
            <origin rpy="0 0 0.0" xyz="0 0 0"/>
            <geometry>
                <mesh filename="package://robot_properties_solo/resources/meshes/anymal/dae/thigh.dae" scale="1.0 1.0 1.0"/>
            </geometry>
        </visual>
        <!-- Thigh collision -->
        <collision>
            <origin rpy="1.57079632679 0 0" xyz="0 0.04 0"/>
            <geometry>
                <cylinder length="0.08" radius="0.065"/>
            </geometry>
        </collision>
        <collision>
            <origin rpy="0 0 0" xyz="0 0.03 -0.1413135"/>
            <geometry>
                <box size="0.075 0.06 0.282627"/>
            </geometry>
        </collision>
        <inertial>
            <origin rpy="0 0 0" xyz="0.0 0.018 -0.169"/>
            <mass value="1.03"/>
            <inertia ixx="0.018644469" ixy="5.2e-08" ixz="1.0157e-05" iyy="0.019312599" iyz="0.002520077" izz="0.002838361"/>
        </inertial>
    </link>
    <!-- joint thigh KFE -->
    <joint name="FL_thigh_fixed_FL_KFE" type="fixed">
        <parent link="FL_thigh_fixed"/>
        <child link="FL_KFE"/>
        <origin rpy="0 0 1.57079632679" xyz="0.0 0.1003 -0.285"/>
    </joint>
    <!-- Drive link -->
    <link name="FL_KFE">
        <visual>
            <origin rpy="0 0 0" xyz="0 0 0"/>
            <geometry>
                <mesh filename="package://robot_properties_solo/resources/meshes/anymal/dae/drive.dae" scale="1.0 1.0 1.0"/>
            </geometry>
        </visual>
        <collision>
            <origin rpy="0 1.57079632679 0" xyz="-0.07 0 0"/>
            <geometry>
                <cylinder length="0.14" radius="0.05"/>
            </geometry>
        </collision>
        <inertial>
            <origin rpy="0 0 0" xyz="-0.063 7e-05 0.00046"/>
            <mass value="2.04"/>
            <inertia ixx="0.001053013" ixy="4.527e-05" ixz="8.855e-05" iyy="0.001805509" iyz="9.909e-05" izz="0.001765827"/>
        </inertial>
    </link>
    <!-- joint Drive output -->
    <joint name="FL_KFE" type="revolute">
        <parent link="FL_KFE"/>
        <child link="FL_SHANK"/>
        <origin rpy="0 0 0" xyz="0 0 0"/>
        <axis xyz="1 0 0"/>
        <limit effort="80.0" lower="-9.42477796077" upper="9.42477796077" velocity="7.5"/>
        <dynamics damping="0.0" friction="0.0"/>
    </joint>
    <!-- Drive output link -->
    <link name="FL_SHANK">
        <inertial>
            <origin rpy="0 0 0" xyz="0 0 0"/>
            <mass value="0.001"/>
            <inertia ixx="0.000001" ixy="0.0" ixz="0.0" iyy="0.000001" iyz="0.0" izz="0.000001"/>
        </inertial>
    </link>
    <!-- joint KFE shank -->
    <joint name="FL_shank_FL_shank_fixed" type="fixed">
        <parent link="FL_SHANK"/>
        <child link="FL_shank_fixed"/>
        <origin rpy="0 0 -1.57079632679" xyz="0 0 0"/>
    </joint>
    <!-- Shank link -->
    <link name="FL_shank_fixed">
        <visual>
            <origin rpy="0 0 0.0" xyz="0 0 0"/>
            <geometry>
                <mesh filename="package://robot_properties_solo/resources/meshes/anymal/dae/shank_l.dae" scale="1.0 1.0 1.0"/>
            </geometry>
        </visual>
        <!-- Shank collision -->
        <collision>
            <origin rpy="1.57079632679 0 0" xyz="0 0.02 0"/>
            <geometry>
                <cylinder length="0.04" radius="0.06"/>
            </geometry>
        </collision>
        <collision>
            <origin rpy="1.57079632679 0 0" xyz="0.057499 0.02 0"/>
            <geometry>
                <box size="0.114998 0.0675 0.04"/>
            </geometry>
        </collision>
        <inertial>
            <origin rpy="0 0 0" xyz="0.03463 0.00688 0.00098"/>
            <mass value="0.33742"/>
            <inertia ixx="0.00032748005" ixy="2.142561e-05" ixz="1.33942e-05" iyy="0.00110974122" iyz="7.601e-08" izz="0.00089388521"/>
        </inertial>
    </link>
    <!-- Leg configurations: xx (knees bent inwards), xo (knees bent backwards) -->
    <!-- joint shank foot -->
    <joint name="FL_shank_fixed_FL_FOOT" type="fixed">
        <parent link="FL_shank_fixed"/>
        <child link="FL_FOOT"/>
        <origin rpy="0 0 0" xyz="0.08795 0.01305 -0.31547"/>
    </joint>
    <!-- Foot link -->
    <link name="FL_FOOT">
        <visual>
            <origin rpy="0 0 -0.785398163397" xyz="0 0 -0.0225"/>
            <geometry>
                <mesh filename="package://robot_properties_solo/resources/meshes/anymal/dae/foot.dae" scale="1.0 1.0 1.0"/>
            </geometry>
        </visual>
        <!-- Adapter collision -->
        <collision>
            <origin rpy="0 0 0" xyz="0 0 0.146485"/>
            <geometry>
                <cylinder length="0.282504" radius="0.0175"/>
            </geometry>
        </collision>
        <!-- Foot collision -->
        <collision>
            <origin xyz="0 0 0.0"/>
            <geometry>
                <sphere radius="0.03"/>
            </geometry>
        </collision>
        <inertial>
            <origin rpy="0 0 0" xyz="0.00948 -0.00948 0.1243"/>
            <mass value="0.25"/>
            <inertia ixx="0.00317174097" ixy="2.63048e-06" ixz="6.815581e-05" iyy="0.00317174092" iyz="6.815583e-05" izz="8.319196e-05"/>
        </inertial>
    </link>
    <!-- joint base HAA -->
    <joint name="base_FR_HAA" type="fixed">
        <parent link="base_link"/>
        <child link="FR_HAA"/>
        <origin rpy="-2.61799387799 0 0.0" xyz="0.2999 -0.104 0.0"/>
    </joint>
    <!-- Drive link -->
    <link name="FR_HAA">
        <visual>
            <origin rpy="0 0 0" xyz="0 0 0"/>
            <geometry>
                <mesh filename="package://robot_properties_solo/resources/meshes/anymal/dae/drive.dae" scale="1.0 1.0 1.0"/>
            </geometry>
        </visual>
        <inertial>
            <origin rpy="0 0 0" xyz="-0.063 7e-05 0.00046"/>
            <mass value="2.04"/>
            <inertia ixx="0.001053013" ixy="4.527e-05" ixz="8.855e-05" iyy="0.001805509" iyz="9.909e-05" izz="0.001765827"/>
        </inertial>
    </link>
    <!-- joint Drive output -->
    <joint name="FR_HAA" type="revolute">
        <parent link="FR_HAA"/>
        <child link="FR_HIP"/>
        <origin rpy="0 0 0" xyz="0 0 0"/>
        <axis xyz="1 0 0"/>
        <limit effort="80.0" lower="-0.72" upper="0.72" velocity="7.5"/>
        <dynamics damping="0.0" friction="0.0"/>
    </joint>
    <!-- Drive output link -->
    <link name="FR_HIP">
        <inertial>
            <origin rpy="0 0 0" xyz="0 0 0"/>
            <mass value="0.001"/>
            <inertia ixx="0.000001" ixy="0.0" ixz="0.0" iyy="0.000001" iyz="0.0" izz="0.000001"/>
        </inertial>
    </link>
    <!-- joint HAA hip -->
    <joint name="FR_HIP_FR_hip_fixed" type="fixed">
        <parent link="FR_HIP"/>
        <child link="FR_hip_fixed"/>
        <origin rpy="2.61799387799 0 0.0" xyz="0 0 0"/>
    </joint>
    <!-- Hip link -->
    <link name="FR_hip_fixed">
        <visual>
            <origin rpy="0 0 0.0" xyz="0 0 0"/>
            <geometry>
                <mesh filename="package://robot_properties_solo/resources/meshes/anymal/dae/hip_r.dae" scale="1.0 1.0 1.0"/>
            </geometry>
        </visual>
        <inertial>
            <origin rpy="0 0 0" xyz="0.048 -0.008 -0.003"/>
            <mass value="0.74"/>
            <inertia ixx="0.001393106" ixy="-8.4012e-05" ixz="2.3378e-05" iyy="0.003798579" iyz="-7.1319e-05" izz="0.003897509"/>
        </inertial>
    </link>
    <!-- joint hip HFE -->
    <joint name="FR_hip_fixed_FR_HFE" type="fixed">
        <parent link="FR_hip_fixed"/>
        <child link="FR_HFE"/>
        <origin rpy="0 0 -1.57079632679" xyz="0.0599 -0.08381 0.0"/>
    </joint>
    <!-- Drive link -->
    <link name="FR_HFE">
        <visual>
            <origin rpy="0 0 0" xyz="0 0 0"/>
            <geometry>
                <mesh filename="package://robot_properties_solo/resources/meshes/anymal/dae/drive.dae" scale="1.0 1.0 1.0"/>
            </geometry>
        </visual>
        <collision>
            <origin rpy="0 1.57079632679 0" xyz="-0.07 0 0"/>
            <geometry>
                <cylinder length="0.14" radius="0.05"/>
            </geometry>
        </collision>
        <inertial>
            <origin rpy="0 0 0" xyz="-0.063 7e-05 0.00046"/>
            <mass value="2.04"/>
            <inertia ixx="0.001053013" ixy="4.527e-05" ixz="8.855e-05" iyy="0.001805509" iyz="9.909e-05" izz="0.001765827"/>
        </inertial>
    </link>
    <!-- joint Drive output -->
    <joint name="FR_HFE" type="revolute">
        <parent link="FR_HFE"/>
        <child link="FR_THIGH"/>
        <origin rpy="0 0 0" xyz="0 0 0"/>
        <axis xyz="-1 0 0"/>
        <limit effort="80.0" lower="-9.42477796077" upper="9.42477796077" velocity="7.5"/>
        <dynamics damping="0.0" friction="0.0"/>
    </joint>
    <!-- Drive output link -->
    <link name="FR_THIGH">
        <inertial>
            <origin rpy="0 0 0" xyz="0 0 0"/>
            <mass value="0.001"/>
            <inertia ixx="0.000001" ixy="0.0" ixz="0.0" iyy="0.000001" iyz="0.0" izz="0.000001"/>
        </inertial>
    </link>
    <!-- joint HFE thigh -->
    <joint name="FR_THIGH_FR_thigh_fixed" type="fixed">
        <parent link="FR_THIGH"/>
        <child link="FR_thigh_fixed"/>
        <origin rpy="0 0 1.57079632679" xyz="0 0 0"/>
    </joint>
    <!-- Thigh link -->
    <link name="FR_thigh_fixed">
        <visual>
            <origin rpy="0 0 -3.14159265359" xyz="0 0 0"/>
            <geometry>
                <mesh filename="package://robot_properties_solo/resources/meshes/anymal/dae/thigh.dae" scale="1.0 1.0 1.0"/>
            </geometry>
        </visual>
        <!-- Thigh collision -->
        <collision>
            <origin rpy="1.57079632679 0 0" xyz="0 -0.04 0"/>
            <geometry>
                <cylinder length="0.08" radius="0.065"/>
            </geometry>
        </collision>
        <collision>
            <origin rpy="0 0 0" xyz="0 -0.03 -0.1413135"/>
            <geometry>
                <box size="0.075 0.06 0.282627"/>
            </geometry>
        </collision>
        <inertial>
            <origin rpy="0 0 0" xyz="0.0 -0.018 -0.169"/>
            <mass value="1.03"/>
            <inertia ixx="0.018644469" ixy="-5.2e-08" ixz="1.0157e-05" iyy="0.019312599" iyz="-0.002520077" izz="0.002838361"/>
        </inertial>
    </link>
    <!-- joint thigh KFE -->
    <joint name="FR_thigh_fixed_FR_KFE" type="fixed">
        <parent link="FR_thigh_fixed"/>
        <child link="FR_KFE"/>
        <origin rpy="0 0 -1.57079632679" xyz="0.0 -0.1003 -0.285"/>
    </joint>
    <!-- Drive link -->
    <link name="FR_KFE">
        <visual>
            <origin rpy="0 0 0" xyz="0 0 0"/>
            <geometry>
                <mesh filename="package://robot_properties_solo/resources/meshes/anymal/dae/drive.dae" scale="1.0 1.0 1.0"/>
            </geometry>
        </visual>
        <collision>
            <origin rpy="0 1.57079632679 0" xyz="-0.07 0 0"/>
            <geometry>
                <cylinder length="0.14" radius="0.05"/>
            </geometry>
        </collision>
        <inertial>
            <origin rpy="0 0 0" xyz="-0.063 7e-05 0.00046"/>
            <mass value="2.04"/>
            <inertia ixx="0.001053013" ixy="4.527e-05" ixz="8.855e-05" iyy="0.001805509" iyz="9.909e-05" izz="0.001765827"/>
        </inertial>
    </link>
    <!-- joint Drive output -->
    <joint name="FR_KFE" type="revolute">
        <parent link="FR_KFE"/>
        <child link="FR_SHANK"/>
        <origin rpy="0 0 0" xyz="0 0 0"/>
        <axis xyz="-1 0 0"/>
        <limit effort="80.0" lower="-9.42477796077" upper="9.42477796077" velocity="7.5"/>
        <dynamics damping="0.0" friction="0.0"/>
    </joint>
    <!-- Drive output link -->
    <link name="FR_SHANK">
        <inertial>
            <origin rpy="0 0 0" xyz="0 0 0"/>
            <mass value="0.001"/>
            <inertia ixx="0.000001" ixy="0.0" ixz="0.0" iyy="0.000001" iyz="0.0" izz="0.000001"/>
        </inertial>
    </link>
    <!-- joint KFE shank -->
    <joint name="FR_shank_FR_shank_fixed" type="fixed">
        <parent link="FR_SHANK"/>
        <child link="FR_shank_fixed"/>
        <origin rpy="0 0 1.57079632679" xyz="0 0 0"/>
    </joint>
    <!-- Shank link -->
    <link name="FR_shank_fixed">
        <visual>
            <origin rpy="0 0 0.0" xyz="0 0 0"/>
            <geometry>
                <mesh filename="package://robot_properties_solo/resources/meshes/anymal/dae/shank_r.dae" scale="1.0 1.0 1.0"/>
            </geometry>
        </visual>
        <!-- Shank collision -->
        <collision>
            <origin rpy="1.57079632679 0 0" xyz="0 -0.02 0"/>
            <geometry>
                <cylinder length="0.04" radius="0.06"/>
            </geometry>
        </collision>
        <collision>
            <origin rpy="1.57079632679 0 0" xyz="0.057499 -0.02 0"/>
            <geometry>
                <box size="0.114998 0.0675 0.04"/>
            </geometry>
        </collision>
        <inertial>
            <origin rpy="0 0 0" xyz="0.03463 -0.00688 0.00098"/>
            <mass value="0.33742"/>
            <inertia ixx="0.00032748005" ixy="-2.142561e-05" ixz="1.33942e-05" iyy="0.00110974122" iyz="-7.601e-08" izz="0.00089388521"/>
        </inertial>
    </link>
    <!-- Leg configurations: xx (knees bent inwards), xo (knees bent backwards) -->
    <!-- joint shank foot -->
    <joint name="FR_shank_fixed_FR_FOOT" type="fixed">
        <parent link="FR_shank_fixed"/>
        <child link="FR_FOOT"/>
        <origin rpy="0 0 0" xyz="0.08795 -0.01305 -0.31547"/>
    </joint>
    <!-- Foot link -->
    <link name="FR_FOOT">
        <visual>
            <origin rpy="0 0 0.785398163397" xyz="0 0 -0.0225"/>
            <geometry>
                <mesh filename="package://robot_properties_solo/resources/meshes/anymal/dae/foot.dae" scale="1.0 1.0 1.0"/>
            </geometry>
        </visual>
        <!-- Adapter collision -->
        <collision>
            <origin rpy="0 0 0" xyz="0 0 0.146485"/>
            <geometry>
                <cylinder length="0.282504" radius="0.0175"/>
            </geometry>
        </collision>
        <!-- Foot collision -->
        <collision>
            <origin xyz="0 0 0.0"/>
            <geometry>
                <sphere radius="0.03"/>
            </geometry>
        </collision>
        <inertial>
            <origin rpy="0 0 0" xyz="0.00948 0.00948 0.1243"/>
            <mass value="0.25"/>
            <inertia ixx="0.00317174097" ixy="-2.63048e-06" ixz="6.815581e-05" iyy="0.00317174092" iyz="-6.815583e-05" izz="8.319196e-05"/>
        </inertial>
    </link>
    <!-- joint base HAA -->
    <joint name="base_HL_HAA" type="fixed">
        <parent link="base_link"/>
        <child link="HL_HAA"/>
        <origin rpy="-2.61799387799 0 -3.14159265359" xyz="-0.2999 0.104 0.0"/>
    </joint>
    <!-- Drive link -->
    <link name="HL_HAA">
        <visual>
            <origin rpy="0 0 0" xyz="0 0 0"/>
            <geometry>
                <mesh filename="package://robot_properties_solo/resources/meshes/anymal/dae/drive.dae" scale="1.0 1.0 1.0"/>
            </geometry>
        </visual>
        <inertial>
            <origin rpy="0 0 0" xyz="-0.063 7e-05 0.00046"/>
            <mass value="2.04"/>
            <inertia ixx="0.001053013" ixy="4.527e-05" ixz="8.855e-05" iyy="0.001805509" iyz="9.909e-05" izz="0.001765827"/>
        </inertial>
    </link>
    <!-- joint Drive output -->
    <joint name="HL_HAA" type="revolute">
        <parent link="HL_HAA"/>
        <child link="HL_HIP"/>
        <origin rpy="0 0 0" xyz="0 0 0"/>
        <axis xyz="-1 0 0"/>
        <limit effort="80.0" lower="-0.72" upper="0.72" velocity="7.5"/>
        <dynamics damping="0.0" friction="0.0"/>
    </joint>
    <!-- Drive output link -->
    <link name="HL_HIP">
        <inertial>
            <origin rpy="0 0 0" xyz="0 0 0"/>
            <mass value="0.001"/>
            <inertia ixx="0.000001" ixy="0.0" ixz="0.0" iyy="0.000001" iyz="0.0" izz="0.000001"/>
        </inertial>
    </link>
    <!-- joint HAA hip -->
    <joint name="HL_HIP_HL_hip_fixed" type="fixed">
        <parent link="HL_HIP"/>
        <child link="HL_hip_fixed"/>
        <origin rpy="-2.61799387799 0 -3.14159265359" xyz="0 0 0"/>
    </joint>
    <!-- Hip link -->
    <link name="HL_hip_fixed">
        <visual>
            <origin rpy="0 0 -3.14159265359" xyz="0 0 0"/>
            <geometry>
                <mesh filename="package://robot_properties_solo/resources/meshes/anymal/dae/hip_r.dae" scale="1.0 1.0 1.0"/>
            </geometry>
        </visual>
        <inertial>
            <origin rpy="0 0 0" xyz="-0.048 0.008 -0.003"/>
            <mass value="0.74"/>
            <inertia ixx="0.001393106" ixy="-8.4012e-05" ixz="-2.3378e-05" iyy="0.003798579" iyz="7.1319e-05" izz="0.003897509"/>
        </inertial>
    </link>
    <!-- joint hip HFE -->
    <joint name="HL_hip_fixed_HL_HFE" type="fixed">
        <parent link="HL_hip_fixed"/>
        <child link="HL_HFE"/>
        <origin rpy="0 0 1.57079632679" xyz="-0.0599 0.08381 0.0"/>
    </joint>
    <!-- Drive link -->
    <link name="HL_HFE">
        <visual>
            <origin rpy="0 0 0" xyz="0 0 0"/>
            <geometry>
                <mesh filename="package://robot_properties_solo/resources/meshes/anymal/dae/drive.dae" scale="1.0 1.0 1.0"/>
            </geometry>
        </visual>
        <collision>
            <origin rpy="0 1.57079632679 0" xyz="-0.07 0 0"/>
            <geometry>
                <cylinder length="0.14" radius="0.05"/>
            </geometry>
        </collision>
        <inertial>
            <origin rpy="0 0 0" xyz="-0.063 7e-05 0.00046"/>
            <mass value="2.04"/>
            <inertia ixx="0.001053013" ixy="4.527e-05" ixz="8.855e-05" iyy="0.001805509" iyz="9.909e-05" izz="0.001765827"/>
        </inertial>
    </link>
    <!-- joint Drive output -->
    <joint name="HL_HFE" type="revolute">
        <parent link="HL_HFE"/>
        <child link="HL_THIGH"/>
        <origin rpy="0 0 0" xyz="0 0 0"/>
        <axis xyz="1 0 0"/>
        <limit effort="80.0" lower="-9.42477796077" upper="9.42477796077" velocity="7.5"/>
        <dynamics damping="0.0" friction="0.0"/>
    </joint>
    <!-- Drive output link -->
    <link name="HL_THIGH">
        <inertial>
            <origin rpy="0 0 0" xyz="0 0 0"/>
            <mass value="0.001"/>
            <inertia ixx="0.000001" ixy="0.0" ixz="0.0" iyy="0.000001" iyz="0.0" izz="0.000001"/>
        </inertial>
    </link>
    <!-- joint HFE thigh -->
    <joint name="HL_THIGH_HL_thigh_fixed" type="fixed">
        <parent link="HL_THIGH"/>
        <child link="HL_thigh_fixed"/>
        <origin rpy="0 0 -1.57079632679" xyz="0 0 0"/>
    </joint>
    <!-- Thigh link -->
    <link name="HL_thigh_fixed">
        <visual>
            <origin rpy="0 0 0.0" xyz="0 0 0"/>
            <geometry>
                <mesh filename="package://robot_properties_solo/resources/meshes/anymal/dae/thigh.dae" scale="1.0 1.0 1.0"/>
            </geometry>
        </visual>
        <!-- Thigh collision -->
        <collision>
            <origin rpy="1.57079632679 0 0" xyz="0 0.04 0"/>
            <geometry>
                <cylinder length="0.08" radius="0.065"/>
            </geometry>
        </collision>
        <collision>
            <origin rpy="0 0 0" xyz="0 0.03 -0.1413135"/>
            <geometry>
                <box size="0.075 0.06 0.282627"/>
            </geometry>
        </collision>
        <inertial>
            <origin rpy="0 0 0" xyz="-0.0 0.018 -0.169"/>
            <mass value="1.03"/>
            <inertia ixx="0.018644469" ixy="-5.2e-08" ixz="-1.0157e-05" iyy="0.019312599" iyz="0.002520077" izz="0.002838361"/>
        </inertial>
    </link>
    <!-- joint thigh KFE -->
    <joint name="HL_thigh_fixed_HL_KFE" type="fixed">
        <parent link="HL_thigh_fixed"/>
        <child link="HL_KFE"/>
        <origin rpy="0 0 1.57079632679" xyz="-0.0 0.1003 -0.285"/>
    </joint>
    <!-- Drive link -->
    <link name="HL_KFE">
        <visual>
            <origin rpy="0 0 0" xyz="0 0 0"/>
            <geometry>
                <mesh filename="package://robot_properties_solo/resources/meshes/anymal/dae/drive.dae" scale="1.0 1.0 1.0"/>
            </geometry>
        </visual>
        <collision>
            <origin rpy="0 1.57079632679 0" xyz="-0.07 0 0"/>
            <geometry>
                <cylinder length="0.14" radius="0.05"/>
            </geometry>
        </collision>
        <inertial>
            <origin rpy="0 0 0" xyz="-0.063 7e-05 0.00046"/>
            <mass value="2.04"/>
            <inertia ixx="0.001053013" ixy="4.527e-05" ixz="8.855e-05" iyy="0.001805509" iyz="9.909e-05" izz="0.001765827"/>
        </inertial>
    </link>
    <!-- joint Drive output -->
    <joint name="HL_KFE" type="revolute">
        <parent link="HL_KFE"/>
        <child link="HL_SHANK"/>
        <origin rpy="0 0 0" xyz="0 0 0"/>
        <axis xyz="1 0 0"/>
        <limit effort="80.0" lower="-9.42477796077" upper="9.42477796077" velocity="7.5"/>
        <dynamics damping="0.0" friction="0.0"/>
    </joint>
    <!-- Drive output link -->
    <link name="HL_SHANK">
        <inertial>
            <origin rpy="0 0 0" xyz="0 0 0"/>
            <mass value="0.001"/>
            <inertia ixx="0.000001" ixy="0.0" ixz="0.0" iyy="0.000001" iyz="0.0" izz="0.000001"/>
        </inertial>
    </link>
    <!-- joint KFE shank -->
    <joint name="HL_shank_HL_shank_fixed" type="fixed">
        <parent link="HL_SHANK"/>
        <child link="HL_shank_fixed"/>
        <origin rpy="0 0 -1.57079632679" xyz="0 0 0"/>
    </joint>
    <!-- Shank link -->
    <link name="HL_shank_fixed">
        <visual>
            <origin rpy="0 0 -3.14159265359" xyz="0 0 0"/>
            <geometry>
                <mesh filename="package://robot_properties_solo/resources/meshes/anymal/dae/shank_r.dae" scale="1.0 1.0 1.0"/>
            </geometry>
        </visual>
        <!-- Shank collision -->
        <collision>
            <origin rpy="1.57079632679 0 0" xyz="0 0.02 0"/>
            <geometry>
                <cylinder length="0.04" radius="0.06"/>
            </geometry>
        </collision>
        <collision>
            <origin rpy="1.57079632679 0 0" xyz="-0.057499 0.02 0"/>
            <geometry>
                <box size="0.114998 0.0675 0.04"/>
            </geometry>
        </collision>
        <inertial>
            <origin rpy="0 0 0" xyz="-0.03463 0.00688 0.00098"/>
            <mass value="0.33742"/>
            <inertia ixx="0.00032748005" ixy="-2.142561e-05" ixz="-1.33942e-05" iyy="0.00110974122" iyz="7.601e-08" izz="0.00089388521"/>
        </inertial>
    </link>
    <!-- Leg configurations: xx (knees bent inwards), xo (knees bent backwards) -->
    <!-- joint shank foot -->
    <joint name="HL_shank_fixed_HL_FOOT" type="fixed">
        <parent link="HL_shank_fixed"/>
        <child link="HL_FOOT"/>
        <origin rpy="0 0 0" xyz="-0.08795 0.01305 -0.31547"/>
    </joint>
    <!-- Foot link -->
    <link name="HL_FOOT">
        <visual>
            <origin rpy="0 0 -2.35619449019" xyz="0 0 -0.0225"/>
            <geometry>
                <mesh filename="package://robot_properties_solo/resources/meshes/anymal/dae/foot.dae" scale="1.0 1.0 1.0"/>
            </geometry>
        </visual>
        <!-- Adapter collision -->
        <collision>
            <origin rpy="0 0 0" xyz="0 0 0.146485"/>
            <geometry>
                <cylinder length="0.282504" radius="0.0175"/>
            </geometry>
        </collision>
        <!-- Foot collision -->
        <collision>
            <origin xyz="0 0 0.0"/>
            <geometry>
                <sphere radius="0.03"/>
            </geometry>
        </collision>
        <inertial>
            <origin rpy="0 0 0" xyz="-0.00948 -0.00948 0.1243"/>
            <mass value="0.25"/>
            <inertia ixx="0.00317174097" ixy="-2.63048e-06" ixz="-6.815581e-05" iyy="0.00317174092" iyz="6.815583e-05" izz="8.319196e-05"/>
        </inertial>
    </link>
    <!-- joint base HAA -->
    <joint name="base_HR_HAA" type="fixed">
        <parent link="base_link"/>
        <child link="HR_HAA"/>
        <origin rpy="2.61799387799 0 -3.14159265359" xyz="-0.2999 -0.104 0.0"/>
    </joint>
    <!-- Drive link -->
    <link name="HR_HAA">
        <visual>
            <origin rpy="0 0 0" xyz="0 0 0"/>
            <geometry>
                <mesh filename="package://robot_properties_solo/resources/meshes/anymal/dae/drive.dae" scale="1.0 1.0 1.0"/>
            </geometry>
        </visual>
        <inertial>
            <origin rpy="0 0 0" xyz="-0.063 7e-05 0.00046"/>
            <mass value="2.04"/>
            <inertia ixx="0.001053013" ixy="4.527e-05" ixz="8.855e-05" iyy="0.001805509" iyz="9.909e-05" izz="0.001765827"/>
        </inertial>
    </link>
    <!-- joint Drive output -->
    <joint name="HR_HAA" type="revolute">
        <parent link="HR_HAA"/>
        <child link="HR_HIP"/>
        <origin rpy="0 0 0" xyz="0 0 0"/>
        <axis xyz="-1 0 0"/>
        <limit effort="80.0" lower="-0.72" upper="0.72" velocity="7.5"/>
        <dynamics damping="0.0" friction="0.0"/>
    </joint>
    <!-- Drive output link -->
    <link name="HR_HIP">
        <inertial>
            <origin rpy="0 0 0" xyz="0 0 0"/>
            <mass value="0.001"/>
            <inertia ixx="0.000001" ixy="0.0" ixz="0.0" iyy="0.000001" iyz="0.0" izz="0.000001"/>
        </inertial>
    </link>
    <!-- joint HAA hip -->
    <joint name="HR_HIP_HR_hip_fixed" type="fixed">
        <parent link="HR_HIP"/>
        <child link="HR_hip_fixed"/>
        <origin rpy="2.61799387799 0 -3.14159265359" xyz="0 0 0"/>
    </joint>
    <!-- Hip link -->
    <link name="HR_hip_fixed">
        <visual>
            <origin rpy="0 0 -3.14159265359" xyz="0 0 0"/>
            <geometry>
                <mesh filename="package://robot_properties_solo/resources/meshes/anymal/dae/hip_l.dae" scale="1.0 1.0 1.0"/>
            </geometry>
        </visual>
        <inertial>
            <origin rpy="0 0 0" xyz="-0.048 -0.008 -0.003"/>
            <mass value="0.74"/>
            <inertia ixx="0.001393106" ixy="8.4012e-05" ixz="-2.3378e-05" iyy="0.003798579" iyz="-7.1319e-05" izz="0.003897509"/>
        </inertial>
    </link>
    <!-- joint hip HFE -->
    <joint name="HR_hip_fixed_HR_HFE" type="fixed">
        <parent link="HR_hip_fixed"/>
        <child link="HR_HFE"/>
        <origin rpy="0 0 -1.57079632679" xyz="-0.0599 -0.08381 0.0"/>
    </joint>
    <!-- Drive link -->
    <link name="HR_HFE">
        <visual>
            <origin rpy="0 0 0" xyz="0 0 0"/>
            <geometry>
                <mesh filename="package://robot_properties_solo/resources/meshes/anymal/dae/drive.dae" scale="1.0 1.0 1.0"/>
            </geometry>
        </visual>
        <collision>
            <origin rpy="0 1.57079632679 0" xyz="-0.07 0 0"/>
            <geometry>
                <cylinder length="0.14" radius="0.05"/>
            </geometry>
        </collision>
        <inertial>
            <origin rpy="0 0 0" xyz="-0.063 7e-05 0.00046"/>
            <mass value="2.04"/>
            <inertia ixx="0.001053013" ixy="4.527e-05" ixz="8.855e-05" iyy="0.001805509" iyz="9.909e-05" izz="0.001765827"/>
        </inertial>
    </link>
    <!-- joint Drive output -->
    <joint name="HR_HFE" type="revolute">
        <parent link="HR_HFE"/>
        <child link="HR_THIGH"/>
        <origin rpy="0 0 0" xyz="0 0 0"/>
        <axis xyz="-1 0 0"/>
        <limit effort="80.0" lower="-9.42477796077" upper="9.42477796077" velocity="7.5"/>
        <dynamics damping="0.0" friction="0.0"/>
    </joint>
    <!-- Drive output link -->
    <link name="HR_THIGH">
        <inertial>
            <origin rpy="0 0 0" xyz="0 0 0"/>
            <mass value="0.001"/>
            <inertia ixx="0.000001" ixy="0.0" ixz="0.0" iyy="0.000001" iyz="0.0" izz="0.000001"/>
        </inertial>
    </link>
    <!-- joint HFE thigh -->
    <joint name="HR_THIGH_HR_thigh_fixed" type="fixed">
        <parent link="HR_THIGH"/>
        <child link="HR_thigh_fixed"/>
        <origin rpy="0 0 1.57079632679" xyz="0 0 0"/>
    </joint>
    <!-- Thigh link -->
    <link name="HR_thigh_fixed">
        <visual>
            <origin rpy="0 0 -3.14159265359" xyz="0 0 0"/>
            <geometry>
                <mesh filename="package://robot_properties_solo/resources/meshes/anymal/dae/thigh.dae" scale="1.0 1.0 1.0"/>
            </geometry>
        </visual>
        <!-- Thigh collision -->
        <collision>
            <origin rpy="1.57079632679 0 0" xyz="0 -0.04 0"/>
            <geometry>
                <cylinder length="0.08" radius="0.065"/>
            </geometry>
        </collision>
        <collision>
            <origin rpy="0 0 0" xyz="0 -0.03 -0.1413135"/>
            <geometry>
                <box size="0.075 0.06 0.282627"/>
            </geometry>
        </collision>
        <inertial>
            <origin rpy="0 0 0" xyz="-0.0 -0.018 -0.169"/>
            <mass value="1.03"/>
            <inertia ixx="0.018644469" ixy="5.2e-08" ixz="-1.0157e-05" iyy="0.019312599" iyz="-0.002520077" izz="0.002838361"/>
        </inertial>
    </link>
    <!-- joint thigh KFE -->
    <joint name="HR_thigh_fixed_HR_KFE" type="fixed">
        <parent link="HR_thigh_fixed"/>
        <child link="HR_KFE"/>
        <origin rpy="0 0 -1.57079632679" xyz="-0.0 -0.1003 -0.285"/>
    </joint>
    <!-- Drive link -->
    <link name="HR_KFE">
        <visual>
            <origin rpy="0 0 0" xyz="0 0 0"/>
            <geometry>
                <mesh filename="package://robot_properties_solo/resources/meshes/anymal/dae/drive.dae" scale="1.0 1.0 1.0"/>
            </geometry>
        </visual>
        <collision>
            <origin rpy="0 1.57079632679 0" xyz="-0.07 0 0"/>
            <geometry>
                <cylinder length="0.14" radius="0.05"/>
            </geometry>
        </collision>
        <inertial>
            <origin rpy="0 0 0" xyz="-0.063 7e-05 0.00046"/>
            <mass value="2.04"/>
            <inertia ixx="0.001053013" ixy="4.527e-05" ixz="8.855e-05" iyy="0.001805509" iyz="9.909e-05" izz="0.001765827"/>
        </inertial>
    </link>
    <!-- joint Drive output -->
    <joint name="HR_KFE" type="revolute">
        <parent link="HR_KFE"/>
        <child link="HR_SHANK"/>
        <origin rpy="0 0 0" xyz="0 0 0"/>
        <axis xyz="-1 0 0"/>
        <limit effort="80.0" lower="-9.42477796077" upper="9.42477796077" velocity="7.5"/>
        <dynamics damping="0.0" friction="0.0"/>
    </joint>
    <!-- Drive output link -->
    <link name="HR_SHANK">
        <inertial>
            <origin rpy="0 0 0" xyz="0 0 0"/>
            <mass value="0.001"/>
            <inertia ixx="0.000001" ixy="0.0" ixz="0.0" iyy="0.000001" iyz="0.0" izz="0.000001"/>
        </inertial>
    </link>
    <!-- joint KFE shank -->
    <joint name="HR_shank_HR_shank_fixed" type="fixed">
        <parent link="HR_SHANK"/>
        <child link="HR_shank_fixed"/>
        <origin rpy="0 0 1.57079632679" xyz="0 0 0"/>
    </joint>
    <!-- Shank link -->
    <link name="HR_shank_fixed">
        <visual>
            <origin rpy="0 0 -3.14159265359" xyz="0 0 0"/>
            <geometry>
                <mesh filename="package://robot_properties_solo/resources/meshes/anymal/dae/shank_l.dae" scale="1.0 1.0 1.0"/>
            </geometry>
        </visual>
        <!-- Shank collision -->
        <collision>
            <origin rpy="1.57079632679 0 0" xyz="0 -0.02 0"/>
            <geometry>
                <cylinder length="0.04" radius="0.06"/>
            </geometry>
        </collision>
        <collision>
            <origin rpy="1.57079632679 0 0" xyz="-0.057499 -0.02 0"/>
            <geometry>
                <box size="0.114998 0.0675 0.04"/>
            </geometry>
        </collision>
        <inertial>
            <origin rpy="0 0 0" xyz="-0.03463 -0.00688 0.00098"/>
            <mass value="0.33742"/>
            <inertia ixx="0.00032748005" ixy="2.142561e-05" ixz="-1.33942e-05" iyy="0.00110974122" iyz="-7.601e-08" izz="0.00089388521"/>
        </inertial>
    </link>
    <!-- Leg configurations: xx (knees bent inwards), xo (knees bent backwards) -->
    <!-- joint shank foot -->
    <joint name="HR_shank_fixed_HR_FOOT" type="fixed">
        <parent link="HR_shank_fixed"/>
        <child link="HR_FOOT"/>
        <origin rpy="0 0 0" xyz="-0.08795 -0.01305 -0.31547"/>
    </joint>
    <!-- Foot link -->
    <link name="HR_FOOT">
        <visual>
            <origin rpy="0 0 -3.92699081699" xyz="0 0 -0.0225"/>
            <geometry>
                <mesh filename="package://robot_properties_solo/resources/meshes/anymal/dae/foot.dae" scale="1.0 1.0 1.0"/>
            </geometry>
        </visual>
        <!-- Adapter collision -->
        <collision>
            <origin rpy="0 0 0" xyz="0 0 0.146485"/>
            <geometry>
                <cylinder length="0.282504" radius="0.0175"/>
            </geometry>
        </collision>
        <!-- Foot collision -->
        <collision>
            <origin xyz="0 0 0.0"/>
            <geometry>
                <sphere radius="0.03"/>
            </geometry>
        </collision>
        <inertial>
            <origin rpy="0 0 0" xyz="-0.00948 0.00948 0.1243"/>
            <mass value="0.25"/>
            <inertia ixx="0.00317174097" ixy="2.63048e-06" ixz="-6.815581e-05" iyy="0.00317174092" iyz="-6.815583e-05" izz="8.319196e-05"/>
        </inertial>
    </link>
    <!-- Fixed joint base hatch -->
    <joint name="base_hatch" type="fixed">
        <parent link="base_link"/>
        <child link="hatch"/>
        <origin rpy="0 0 0" xyz="0.0 0.0 0.0"/>
    </joint>
    <!-- Hatch link -->
    <link name="hatch">
        <visual>
            <origin rpy="0 0 0" xyz="0.116 0 0.073"/>
            <geometry>
                <mesh filename="package://robot_properties_solo/resources/meshes/anymal/dae/hatch.dae" scale="1.0 1.0 1.0"/>
            </geometry>
        </visual>
        <inertial>
            <origin rpy="0 0 0" xyz="0.116 0.0 0.0758"/>
            <mass value="0.142"/>
            <inertia ixx="0.001" ixy="0.001" ixz="0.001" iyy="0.001" iyz="0.001" izz="0.001"/>
        </inertial>
    </link>
</robot>
